<?xml version="1.0" encoding="utf-8"?>
<!-- =================================================================================== -->
<!-- |    This document was autogenerated by xacro from tx40.xacro                     | -->
<!-- |    EDITING THIS FILE BY HAND IS NOT RECOMMENDED                                 | -->
<!-- =================================================================================== -->
<robot name="staubli_tx40">
  <!-- colours based on RAL values supplied by Staubli -->
  <!-- all RAL colours converted using http://www.visual-graphics.de/en/customer-care/ral-colours -->
  <!-- default colours for robots -->
  <!-- links: main serial chain -->
  <link name="base_link">
    <visual>
      <origin rpy="0 0 0" xyz="0 0 0"/>
      <geometry>
        <mesh filename="package://staubli_tx40_support/meshes/visual/base_link.stl"/>
      </geometry>
      <material name="">
        <color rgba="1.0 0.607843137255 0.0 1.0"/>
      </material>
    </visual>
    <collision>
      <origin rpy="0 0 0" xyz="0 0 0"/>
      <geometry>
        <mesh filename="package://staubli_tx40_support/meshes/collision/base_link.stl"/>
      </geometry>
    </collision>
    <!--
      <inertial>
        <mass value="5.82375"/>
        <origin xyz="-0.00892 -0.00017 0.07857" rpy="0.0 0.0 0.0"/>
        <inertia ixx="0.020725706" ixy="0.00008955" ixz="0.00193426"
                                     iyy="0.026779837"  iyz="0.000024618"
                                                          izz="0.021448879"/>
      </inertial>
      -->
  </link>
  <link name="link_1">
    <visual>
      <origin rpy="0 0 0" xyz="0 0 0"/>
      <geometry>
        <mesh filename="package://staubli_tx40_support/meshes/visual/link_1.stl"/>
      </geometry>
      <material name="">
        <color rgba="1.0 0.607843137255 0.0 1.0"/>
      </material>
    </visual>
    <collision>
      <origin rpy="0 0 0" xyz="0 0 0"/>
      <geometry>
        <mesh filename="package://staubli_tx40_support/meshes/collision/link_1.stl"/>
      </geometry>
    </collision>
    <inertial>
      <mass value="8.81740"/>
      <origin rpy="0.0 0.0 0.0" xyz="-0.00029 0.00931 -0.03386"/>
      <inertia ixx="0.050149637" ixy="0.000391605" ixz="400337.06" iyy="0.043332881" iyz="0.003817008" izz="0.032839343"/>
    </inertial>
  </link>
  <link name="link_2">
    <visual>
      <origin rpy="0 0 0" xyz="0 0 0"/>
      <geometry>
        <mesh filename="package://staubli_tx40_support/meshes/visual/link_2.stl"/>
      </geometry>
      <material name="">
        <color rgba="1.0 0.607843137255 0.0 1.0"/>
      </material>
    </visual>
    <collision>
      <origin rpy="0 0 0" xyz="0 0 0"/>
      <geometry>
        <mesh filename="package://staubli_tx40_support/meshes/collision/link_2.stl"/>
      </geometry>
    </collision>
    <inertial>
      <mass value="6.12815"/>
      <origin rpy="0.0 0.0 0.0" xyz="0.00008 0.14711 0.10312"/>
      <inertia ixx="0.056410712" ixy="-0.000058219" ixz="0.000080107" iyy="0.060088807" iyz="-0.000308218" izz="0.010289325"/>
    </inertial>
  </link>
  <link name="link_3">
    <visual>
      <origin rpy="0 0 0" xyz="0 0 0"/>
      <geometry>
        <mesh filename="package://staubli_tx40_support/meshes/visual/link_3.stl"/>
      </geometry>
      <material name="">
        <color rgba="1.0 0.607843137255 0.0 1.0"/>
      </material>
    </visual>
    <collision>
      <origin rpy="0 0 0" xyz="0 0 0"/>
      <geometry>
        <mesh filename="package://staubli_tx40_support/meshes/collision/link_3.stl"/>
      </geometry>
    </collision>
    <inertial>
      <mass value="3.36342"/>
      <origin rpy="0.0 0.0 0.0" xyz="0.00765 0.01281 -0.01551"/>
      <inertia ixx="0.008592818" ixy="0.000098473" ixz="-0.000358456" iyy="0.008894321" iyz="-0.000370698" izz="0.006740357"/>
    </inertial>
  </link>
  <link name="link_4">
    <visual>
      <origin rpy="0 0 0" xyz="0 0 0"/>
      <geometry>
        <mesh filename="package://staubli_tx40_support/meshes/visual/link_4.stl"/>
      </geometry>
      <material name="">
        <color rgba="1.0 0.607843137255 0.0 1.0"/>
      </material>
    </visual>
    <collision>
      <origin rpy="0 0 0" xyz="0 0 0"/>
      <geometry>
        <mesh filename="package://staubli_tx40_support/meshes/collision/link_4.stl"/>
      </geometry>
    </collision>
    <inertial>
      <mass value="2.63788"/>
      <origin rpy="0.0 0.0 0.0" xyz="-0.00283 0.00 0.14236"/>
      <inertia ixx="0.009920969" ixy="0.000000028" ixz="-0.000208997" iyy="0.008812832" iyz="0.000000954" izz="0.00406691"/>
    </inertial>
  </link>
  <link name="link_5">
    <visual>
      <origin rpy="0 0 0" xyz="0 0 0"/>
      <geometry>
        <mesh filename="package://staubli_tx40_support/meshes/visual/link_5.stl"/>
      </geometry>
      <material name="">
        <color rgba="0.529411764706 0.521568627451 0.505882352941 1.0"/>
      </material>
    </visual>
    <collision>
      <origin rpy="0 0 0" xyz="0 0 0"/>
      <geometry>
        <mesh filename="package://staubli_tx40_support/meshes/collision/link_5.stl"/>
      </geometry>
    </collision>
    <inertial>
      <mass value="0.21237"/>
      <origin rpy="0.0 0.0 0.0" xyz="0.00 0.00 0.01975"/>
      <inertia ixx="0.000117818" ixy="0.00" ixz="-0.000000003" iyy="0.000132032" iyz="-0.00000000345" izz="0.000054314"/>
    </inertial>
  </link>
  <link name="link_6">
    <visual>
      <origin rpy="0 0 0" xyz="0 0 0"/>
      <geometry>
        <mesh filename="package://staubli_tx40_support/meshes/visual/link_6.stl"/>
      </geometry>
      <material name="">
        <color rgba="0.529411764706 0.521568627451 0.505882352941 1.0"/>
      </material>
    </visual>
    <collision>
      <origin rpy="0 0 0" xyz="0 0 0"/>
      <geometry>
        <mesh filename="package://staubli_tx40_support/meshes/collision/link_6.stl"/>
      </geometry>
    </collision>
    <inertial>
      <mass value="0.01746"/>
      <origin rpy="0.0 0.0 0.0" xyz="-0.00023 0.00 -0.00463"/>
      <inertia ixx="0.000002221" ixy="0.00" ixz="-0.000000005" iyy="0.000002156" iyz="0.0" izz="0.000004187"/>
    </inertial>
  </link>
  <!-- joints: main serial chain -->
  <joint name="joint_1" type="revolute">
    <origin rpy="0 0 0" xyz="0 0 0.32"/>
    <parent link="base_link"/>
    <child link="link_1"/>
    <axis xyz="0 0 1"/>
    <limit effort="40.0" lower="-3.14159265359" upper="3.14159265359" velocity="5.00909495322"/>
    <dynamics damping="0.0" friction="0.0"/>
  </joint>
  <joint name="joint_2" type="revolute">
    <origin rpy="0 0 0" xyz="0 0 0"/>
    <parent link="link_1"/>
    <child link="link_2"/>
    <axis xyz="0 1 0"/>
    <limit effort="11.0" lower="-2.18166156499" upper="2.18166156499" velocity="5.00909495322"/>
    <dynamics damping="0.0" friction="0.0"/>
  </joint>
  <joint name="joint_3" type="revolute">
    <origin rpy="0 0 0" xyz="0 0.035 0.225"/>
    <parent link="link_2"/>
    <child link="link_3"/>
    <axis xyz="0 1 0"/>
    <limit effort="8.0" lower="-2.40855436775" upper="2.40855436775" velocity="7.50491578358"/>
    <dynamics damping="0.0" friction="0.0"/>
  </joint>
  <joint name="joint_4" type="revolute">
    <origin rpy="0 0 0" xyz="0 0 0"/>
    <parent link="link_3"/>
    <child link="link_4"/>
    <axis xyz="0 0 1"/>
    <limit effort="4.0" lower="-4.71238898038" upper="4.71238898038" velocity="7.15584993318"/>
    <dynamics damping="0.0" friction="0.0"/>
  </joint>
  <joint name="joint_5" type="revolute">
    <origin rpy="0 0 0" xyz="0 0 0.225"/>
    <parent link="link_4"/>
    <child link="link_5"/>
    <axis xyz="0 1 0"/>
    <limit effort="2.6" lower="-2.09439510239" upper="2.33001455141" velocity="5.58505360638"/>
    <dynamics damping="0.0" friction="0.0"/>
  </joint>
  <joint name="joint_6" type="revolute">
    <origin rpy="0 0 0" xyz="0 0 0.065"/>
    <parent link="link_5"/>
    <child link="link_6"/>
    <axis xyz="0 0 1"/>
    <limit effort="1.4" lower="-4.71238898038" upper="4.71238898038" velocity="12.217304764"/>
    <dynamics damping="0.0" friction="0.0"/>
  </joint>
  
  
  <!-- ROS-Industrial 'base' frame: base_link to Staubli World Coordinates transform -->
  
  <link name="base"/>
  <joint name="base_link-base" type="fixed">
    <origin rpy="0 0 0" xyz="0 0 0.32"/>
    <parent link="base_link"/>
    <child link="base"/>
  </joint>
  
  <!-- ROS-Industrial 'flange' frame: attachment point for EEF models -->
  
  <link name="flange"/>
  <joint name="joint_6-flange" type="fixed">
    <origin rpy="0 -1.57079632679 0" xyz="0 0 0"/>
    <parent link="link_6"/>
    <child link="flange"/>
  </joint>
  
  <!-- ROS-Industrial 'tool0' frame: all-zeros tool frame -->
  <link name="tool0"/>
  <joint name="flange-tool0" type="fixed">
    <origin rpy="0 1.57079632679 0" xyz="0 0 0"/>
    <parent link="flange"/>
    <child link="tool0"/>
  </joint>
</robot>

