<?xml version="1.0"?>
<robot xmlns:xacro="http://wiki.ros.org/xacro">
  <xacro:include filename="$(find staubli_resources)/urdf/common_materials.xacro"/>

  <xacro:macro name="staubli_tx40" params="prefix">
    <!-- links: main serial chain -->
    <link name="${prefix}base_link">
      <visual>
        <origin xyz="0 0 0" rpy="0 0 0"/>
        <geometry>
          <mesh filename="package://staubli_tx40_support/meshes/visual/base_link.stl"/>
        </geometry>
        <xacro:material_staubli_ral_melon_yellow />
      </visual>
      <collision>
        <origin xyz="0 0 0" rpy="0 0 0"/>
        <geometry>
          <mesh filename="package://staubli_tx40_support/meshes/collision/base_link.stl"/>
        </geometry>
      </collision>
      <!--
      <inertial>
        <mass value="5.82375"/>
        <origin xyz="-0.00892 -0.00017 0.07857" rpy="0.0 0.0 0.0"/>
        <inertia ixx="0.020725706" ixy="0.00008955" ixz="0.00193426"
                                     iyy="0.026779837"  iyz="0.000024618"
                                                          izz="0.021448879"/>
      </inertial>
      -->
    </link>
    <link name="${prefix}link_1">
      <visual>
        <origin xyz="0 0 0" rpy="0 0 0"/>
        <geometry>
          <mesh filename="package://staubli_tx40_support/meshes/visual/link_1.stl"/>
        </geometry>
        <xacro:material_staubli_ral_melon_yellow />
      </visual>
      <collision>
        <origin xyz="0 0 0" rpy="0 0 0"/>
        <geometry>
          <mesh filename="package://staubli_tx40_support/meshes/collision/link_1.stl"/>
        </geometry>
      </collision>
      <inertial>
        <mass value="8.81740"/>
        <origin xyz="-0.00029 0.00931 -0.03386" rpy="0.0 0.0 0.0"/>
        <inertia ixx="0.050149637" ixy="0.000391605" ixz="400337.06"
                                     iyy="0.043332881"  iyz="0.003817008"
                                                          izz="0.032839343"/>
      </inertial>
    </link>
    <link name="${prefix}link_2">
      <visual>
        <origin xyz="0 0 0" rpy="0 0 0"/>
        <geometry>
          <mesh filename="package://staubli_tx40_support/meshes/visual/link_2.stl"/>
        </geometry>
        <xacro:material_staubli_ral_melon_yellow />
      </visual>
      <collision>
        <origin xyz="0 0 0" rpy="0 0 0"/>
        <geometry>
          <mesh filename="package://staubli_tx40_support/meshes/collision/link_2.stl"/>
        </geometry>
      </collision>
      <inertial>
        <mass value="6.12815"/>
        <origin xyz="0.00008 0.14711 0.10312" rpy="0.0 0.0 0.0"/>
        <inertia ixx="0.056410712" ixy="-0.000058219" ixz="0.000080107"
                                     iyy="0.060088807" iyz="-0.000308218"
                                                         izz="0.010289325"/>
      </inertial>
    </link>
    <link name="${prefix}link_3">
      <visual>
        <origin xyz="0 0 0" rpy="0 0 0"/>
        <geometry>
          <mesh filename="package://staubli_tx40_support/meshes/visual/link_3.stl"/>
        </geometry>
        <xacro:material_staubli_ral_melon_yellow />
      </visual>
      <collision>
        <origin xyz="0 0 0" rpy="0 0 0"/>
        <geometry>
          <mesh filename="package://staubli_tx40_support/meshes/collision/link_3.stl"/>
        </geometry>
      </collision>
      <inertial>
        <mass value="3.36342"/>
        <origin xyz="0.00765 0.01281 -0.01551" rpy="0.0 0.0 0.0"/>
        <inertia ixx="0.008592818" ixy="0.000098473" ixz="-0.000358456"
                                     iyy="0.008894321"  iyz="-0.000370698"
                                                          izz="0.006740357"/>
      </inertial>
    </link>
    <link name="${prefix}link_4">
      <visual>
        <origin xyz="0 0 0" rpy="0 0 0"/>
        <geometry>
          <mesh filename="package://staubli_tx40_support/meshes/visual/link_4.stl"/>
        </geometry>
        <xacro:material_staubli_ral_melon_yellow />
      </visual>
      <collision>
        <origin xyz="0 0 0" rpy="0 0 0"/>
        <geometry>
          <mesh filename="package://staubli_tx40_support/meshes/collision/link_4.stl"/>
        </geometry>
      </collision>
      <inertial>
        <mass value="2.63788"/>
        <origin xyz="-0.00283 0.00 0.14236" rpy="0.0 0.0 0.0"/>
        <inertia ixx="0.009920969" ixy="0.000000028" ixz="-0.000208997"
                                     iyy="0.008812832"  iyz="0.000000954"
                                                          izz="0.00406691"/>
      </inertial>
    </link>
    <link name="${prefix}link_5">
      <visual>
        <origin xyz="0 0 0" rpy="0 0 0"/>
        <geometry>
          <mesh filename="package://staubli_tx40_support/meshes/visual/link_5.stl"/>
        </geometry>
        <xacro:material_staubli_ral_grey_aluminium />
      </visual>
      <collision>
        <origin xyz="0 0 0" rpy="0 0 0"/>
        <geometry>
          <mesh filename="package://staubli_tx40_support/meshes/collision/link_5.stl"/>
        </geometry>
      </collision>
      <inertial>
        <mass value="0.21237"/>
        <origin xyz="0.00 0.00 0.01975" rpy="0.0 0.0 0.0"/>
        <inertia ixx="0.000117818" ixy="0.00"          ixz="-0.000000003"
                                     iyy="0.000132032" iyz="-0.00000000345"
                                                         izz="0.000054314"/>
      </inertial>
    </link>
    <link name="${prefix}link_6">
      <visual>
        <origin xyz="0 0 0" rpy="0 0 0"/>
        <geometry>
          <mesh filename="package://staubli_tx40_support/meshes/visual/link_6.stl"/>
        </geometry>
        <xacro:material_staubli_ral_grey_aluminium />
      </visual>
      <collision>
        <origin xyz="0 0 0" rpy="0 0 0"/>
        <geometry>
          <mesh filename="package://staubli_tx40_support/meshes/collision/link_6.stl"/>
        </geometry>
      </collision>
      <inertial>
        <mass value="0.01746"/>
        <origin xyz="-0.00023 0.00 -0.00463" rpy="0.0 0.0 0.0"/>
        <inertia ixx="0.000002221" ixy="0.00"          ixz="-0.000000005"
                                     iyy="0.000002156" iyz="0.0"
                                                         izz="0.000004187"/>
      </inertial>
    </link>

    <!-- joints: main serial chain -->
    <joint name="${prefix}joint_1" type="revolute">
      <origin xyz="0 0 0.32" rpy="0 0 0"/>
      <parent link="${prefix}base_link"/>
      <child link="${prefix}link_1"/>
      <axis xyz="0 0 1"/>
      <limit lower="${radians(-180.0)}" upper="${radians(180.0)}" effort="40.0" velocity="${radians(287.0)}" />
      <dynamics damping="0.0" friction="0.0"/>
    </joint>
    <joint name="${prefix}joint_2" type="revolute">
      <origin xyz="0 0 0" rpy="0 0 0"/>
      <parent link="${prefix}link_1"/>
      <child link="${prefix}link_2"/>
      <axis xyz="0 1 0"/>
      <limit lower="${radians(-125.0)}" upper="${radians(125.0)}" effort="11.0" velocity="${radians(287.0)}" />
      <dynamics damping="0.0" friction="0.0"/>
    </joint>
    <joint name="${prefix}joint_3" type="revolute">
      <origin xyz="0 0.035 0.225" rpy="0 0 0"/>
      <parent link="${prefix}link_2"/>
      <child link="${prefix}link_3"/>
      <axis xyz="0 1 0"/>
      <limit lower="${radians(-138.0)}" upper="${radians(138.0)}" effort="8.0" velocity="${radians(430.0)}" />
      <dynamics damping="0.0" friction="0.0"/>
    </joint>
    <joint name="${prefix}joint_4" type="revolute">
      <origin xyz="0 0 0" rpy="0 0 0"/>
      <parent link="${prefix}link_3"/>
      <child link="${prefix}link_4"/>
      <axis xyz="0 0 1"/>
      <limit lower="${radians(-270.0)}" upper="${radians(270.0)}" effort="4.0" velocity="${radians(410.0)}" />
      <dynamics damping="0.0" friction="0.0"/>
    </joint>
    <joint name="${prefix}joint_5" type="revolute">
      <origin xyz="0 0 0.225" rpy="0 0 0"/>
      <parent link="${prefix}link_4"/>
      <child link="${prefix}link_5"/>
      <axis xyz="0 1 0"/>
      <limit lower="${radians(-120.0)}" upper="${radians(133.5)}" effort="2.6" velocity="${radians(320.0)}" />
      <dynamics damping="0.0" friction="0.0"/>
    </joint>
    <joint name="${prefix}joint_6" type="revolute">
      <origin xyz="0 0 0.065" rpy="0 0 0"/>
      <parent link="${prefix}link_5"/>
      <child link="${prefix}link_6"/>
      <axis xyz="0 0 1"/>
      <limit lower="${radians(-270.0)}" upper="${radians(270.0)}" effort="1.4" velocity="${radians(700.0)}" />
      <dynamics damping="0.0" friction="0.0"/>
    </joint>


    <!-- ROS-Industrial 'base' frame: base_link to Staubli World Coordinates transform -->
    <link name="${prefix}base" />
    <joint name="${prefix}base_link-base" type="fixed">
      <origin xyz="0 0 0.32" rpy="0 0 0"/>
      <parent link="${prefix}base_link"/>
      <child link="${prefix}base"/>
    </joint>

    <!-- ROS-Industrial 'flange' frame: attachment point for EEF models -->
    <link name="${prefix}flange" />
    <joint name="${prefix}joint_6-flange" type="fixed">
      <origin xyz="0 0 0" rpy="0 ${radians(-90.0)} 0" />
      <parent link="${prefix}link_6" />
      <child link="${prefix}flange" />
    </joint>

    <!-- ROS-Industrial 'tool0' frame: all-zeros tool frame -->
    <link name="${prefix}tool0" />
    <joint name="${prefix}flange-tool0" type="fixed">
      <origin xyz="0 0 0" rpy="0 ${radians(90.0)} 0" />
      <parent link="${prefix}flange" />
      <child link="${prefix}tool0" />
    </joint>


    <!-- Custom frame -->

    <link name="${prefix}custom" />
    <joint name="${prefix}custom-frame" type="fixed">
      <origin xyz="-0.108687 0.178755 0.324798" rpy="0.0 0.0 0.0"/>
      <parent link="${prefix}base_link"/>
      <child link="${prefix}custom"/>
    </joint>


  </xacro:macro>
</robot>
